Workbook

Sheet KOMPONEN A
B3: KOMPONEN A | I3: MARKAH
B4: KEPERLUAN UTAMA PELAKSANAAN | D4: 1 | E4: 2 | F4: 3 | G4: 4 | H4: 5 | I4: ZON EFFEKTIF | J4: ZON KOMITED | K4: ZON SEPAKAT | L4: ZON AKTIF
B5: A1) DASAR EKSA
B6: 1 | C6: Menyediakan panduan atau Standard Operasi Prosedur (SOP) selaras dengan Dasar EKSA agensi | D6: Panduan / SOP tidak disediakan | E6: Panduan/ SOP disediakan tetapi belum diluluskan oleh pihak pengurusan agensi | F6: Panduan/ SOP disediakan dan diedarkan kepada sebahagian warga agensi yang terlibat secara langsung dalam pelaksanaan EKSA | G6: Panduan/ SOP diluluskan oleh pihak pengurusan dan telah diedarkan kepada semua unit terlibat | H6: Panduan/ SOP diluluskan, disebarkan kepada semua warga agensi, dan dijadikan rujukan utama dalam pelaksanaan EKSA secara menyeluruh | I6: 5 | J6: 5 | K6: 5 | L6: 5
B7: 2 | C7: Menyebar Dasar dan Panduan/ SOP EKSA serta memastikan semua warga kerja memahaminya | D7: Dasar dan Panduan/ SOP EKSA tidak disebarkan | E7: Dasar dan Panduan/ SOP EKSA hanya disebarkan kepada sebahagian warga agensi | F7: Dasar dan Panduan/ SOP EKSA disebarkan dan difahami oleh sebahagian warga agensi | G7: Dasar dan Panduan/ SOP EKSA disebarkan dan difahami oleh warga agensi | H7: Dasar dan Panduan/ SOP EKSA disebarkan dan difahami oleh semua warga agensi serta dijadikan rujukan dalam amalan harian | I7: 5 | J7: 5 | K7: 5 | L7: 5
B8: 3 | C8: Memastikan EKSA Diamalkan dan Dipatuhi | D8: EKSA tidak diamalkan dan dipatuhi oleh warga agensi | E8: EKSA hanya diamalkan dan dipatuhi oleh sebahagian warga agensi | F8: EKSA diamalkan dan dipatuhi oleh warga agensi dalam aktiviti tertentu sahaja | G8: EKSA diamalkan dan dipatuhi oleh semua warga agensi dalam aktiviti berkala | H8: EKSA diamalkan dan dipatuhi secara konsisten oleh semua warga agensi serta menjadi budaya kerja | I8: 5 | J8: 5 | K8: 5 | L8: 5
B9: 4 | C9: Dokumentasi EKSA Sentiasa Dikemas Kini | D9: Semua dokumentasi tidak teratur dan tidak dikemas kini | E9: Sebahagian dokumentasi disusun tetapi tidak dikemas kini secara berkala | F9: Sebahagian dokumentasi teratur dan dikemas kini secara tidak konsisten | G9: Semua dokumentasi teratur dan dikemas kini secara berkala | H9: Semua dokumentasi teratur, dikemas kini secara berkala, dan disimpan dalam sistem rujukan rasmi agensi | I9: 4 | J9: 4 | K9: 4 | L9: 4
B10: 5 | C10: Mewujudkan keseragaman pelaksanaan EKSA seperti kelatan agensi/garis panduan yang digunakan oleh agensi | D10: Tiada keseragaman | E10: Keseragaman hanya dilaksanakan di sebahagian unit/zon | F10: Keseragaman dilaksanakan di kebanyakan unit/zon | G10: Keseragaman dilaksanakan di seluruh unit/zon agensi | H10: Keseragaman dilaksanakan di seluruh agensi dan diperkukuh dengan elemen kreatif dan inovatif | I10: 3 | J10: 3 | K10: 3 | L10: 3
B11: 6 | C11: Menyediakan dan memaparkan sudut EKSA di tempat yang strategik (secara digital atau fizikal) dan mengandungi perkara seperti berikut: - Dasar EKSA agensi - Carta organisasi - Gambar aktiviti sebelum dan selepas - Pelan lantai - Carta perbelanjaan semasa - Informasi hebahan - Tarikh kemas kini sudut EKSA | D11: Sudut EKSA tidak disediakan | E11: Sudut EKSA disediakan tetapi hanya mengandungi dua perkara seperti dicadangkan | F11: Sudut EKSA disediakan tetapi hanya mengandungi tiga hingga empat perkara seperti dicadangkan | G11: Sudut EKSA mengandungi semua perkara seperti dicadangkan | H11: Sudut EKSA mengandungi semua perkara seperti dicadangkan serta dipaparkan secara kreatif dan inovatif | I11: 5 | J11: 5 | K11: 5 | L11: 5
B12: 7 | C12: Memastikan maklumat dan bahan yang dipaparkan sentiasa dikemas kini dan dalam keadaan baik | D12: Sudut EKSA tidak disediakan | E12: Sudut EKSA disediakan tetapi tidak lengkap dan tidak dikemas kini | F12: Sudut EKSA disediakan dengan sebahagian elemen dan dikemas kini secara tidak konsisten | G12: Sudut EKSA disediakan dengan semua elemen dan dikemas kini secara berkala | H12: Sudut EKSA disediakan dengan semua elemen, dikemas kini secara berkala, dan dipaparkan secara kreatif dan inovatif | I12: 3 | J12: 3 | K12: 3 | L12: 3
B13: A2) JAWATANKUASA PELAKSANA EKSA
B14: 8 | C14: Menubuh dan dan melantik Jawatankuasa Pelaksana EKSA yang merangkumi jawatan berikut: - Latihan - Promosi - Audit | D14: Jawatankuasa belum dibentuk dan dilanti | E14: Jawatankuasa telah dibentuk dan dilantik tetapi hanya melibatkan satu jawatankuasa sahaja | F14: Jawatankuasa telah dibentuk dan dilantik tetapi hanya mempunyai dua jawatankuasa yang disyorkan | G14: Jawatankuasa telah dibentuk dan dilantik serta mempunyai tiga jawatankuasa yang disyorkan | H14: Jawatankuasa telah dibentuk dan dilantik serta mempunyai semua jawatankuasa yang disyorkan dan aktif melaksanakan peranan masing-masing | I14: 5 | J14: 5 | K14: 5 | L14: 5
B15: 9 | C15: Merancang dan melaksanakan program/aktiviti EKSA secara berterusan seperti yang berikut: - gotong-royong - kitar semula - kebersihan - penambahbaikan - promosi - latihan | D15: Program/aktiviti EKSA belum dirancang dan dilaksanakan | E15: Program/aktiviti EKSA dirancang tetapi tidak dilaksanakan | F15: Program/aktiviti EKSA dirancang dan dilaksanakan secara tidak berkala | G15: Program/aktiviti EKSA dirancang dan dilaksanakan secara berkala | H15: Program/aktiviti EKSA dirancang dan dilaksanakan secara berkala serta dinilai keberkesanannya melalui laporan dan maklum balas warga agensi | I15: 3 | J15: 3 | K15: 3 | L15: 3
B16: A3) PENGLIBATAN PENGURUSAN ATASAN
B17: 10 | C17: Melibatkan pengurusan atasan sebagai peneraju inisiatif EKSA | D17: Pengurusan atasan tidak terlibat langsung dalam inisiatif EKSA | E17: Pengurusan atasan hanya menyokong secara umum tetapi tidak terlibat dalam perancangan atau pelaksanaan | F17: Mempunyai program kesedaran/pendedahan kepada pengurusan atasan tentang inisiatif EKSA | G17: Mempunyai program kesedaran/pendedahan dan pengurusan atasan terlibat dalam aktiviti EKSA secara berkala | H17: Pengurusan atasan bertindak sebagai peneraju rasmi inisiatif EKSA dan menjadi contoh kepada warga agensi | I17: 5 | J17: 5 | K17: 5 | L17: 5
B18: 11 | C18: Melibatkan pengurusan atasan dalam aktiviti EKSA seperti gotong-royong, audit dan sebagainya | D18: Pengurusan atasan tidak terlibat langsung dalam aktiviti EKSA | E18: Pengurusan atasan hanya hadir secara simbolik tanpa penglibatan aktif | F18: Mempunyai program kesedaran/pendedahan terhadap aktiviti EKSA tetapi pengurusan atasan tidak terlibat | G18: Mempunyai program kesedaran/pendedahan dan pengurusan atasan terlibat dalam sebahagian aktiviti EKSA | H18: Pengurusan atasan aktif menyertai dan memimpin aktiviti EKSA secara konsiste | I18: 5 | J18: 5 | K18: 5 | L18: 5
B19: 12 | C19: Penglibatan pengurusan atasan dalam aktiviti EKSA bersama masyarakat persekitaran | D19: Tiada aktiviti EKSA dijalankan bersama masyarakat persekitaran | E19: Aktiviti EKSA dijalankan bersama masyarakat tetapi tanpa penglibatan pengurusan atasan | F19: Sebahagian aktiviti EKSA dijalankan bersama masyarakat dengan penglibatan pengurusan atasan | G19: Sebahagian besar aktiviti EKSA dijalankan bersama masyarakat dengan penglibatan aktif pengurusan atasan | H19: Pengurusan atasan aktif memimpin aktiviti EKSA bersama masyarakat dan menjadi duta kepada inisiatif tersebut | I19: 1 | J19: 1 | K19: 1 | L19: 1
B20: A4) PEMBUDAYAAN KREATIVITI DAN INOVASI
B21: 13 | C21: Melaksanakan inovasi/amalan baik (best practice) yang boleh meningkatkan produktiviti dan kualiti kerja warga | D21: Inovasi/amalan baik (best practice) tidak dilaksanakan | E21: Inovasi/amalan baik (best practice) dirancang tetapi tidak dilaksanakan | F21: Inovasi/amalan baik (best practice) hanya dilaksanakan sekali sahaja tanpa sebarang penambahbaikan | G21: novasi/amalan baik (best practice) dilaksanakan secara berkala (sekali atau dua kali setahun) | H21: Inovasi/amalan baik (best practice) dilaksanakan secara berkala bagi menambahbaik sistem kerja warga dan disebarkan sebagai contoh amalan terbaik | I21: 1 | J21: 1 | K21: 1 | L21: 1
B22: 14 | C22: Melaksanakan program kreativiti dan inovasi seperti contoh berikut: - Kreativiti menggunakan barangan terpakai - Mengubah suai bahan terpakai untuk hiasan - Mengubah suai peralatan bagi kegunaan EKSA | D22: Program kreativiti dan inovasi tidak dilaksanakan | E22: Program kreativiti dan inovasi dirancang tetapi tidak dilaksanakan | F22: Program kreativiti dan inovasi hanya dilaksanakan sekali sahaja tanpa penyertaan warga agensi | G22: Program kreativiti dan inovasi dilaksanakan tiga kali setahun dengan penyertaan terhad | H22: Program kreativiti dan inovasi dilaksanakan secara konsisten dengan penyertaan aktif warga agensi dan impak positif terhadap persekitaran kerja | I22: 1 | J22: 1 | K22: 1 | L22: 1
B23: A5) TINDAKAN PENJIMATAN/ GO GREEN
B24: 15 | C24: Melaksanakan program penjimatan tenaga/sumber secara menyeluruh seperti contoh berikut: - Notis/arahan penjimatan tenaga - Penggunaan lampu/peralatan jimat tenaga - Penetapan suhu optimum - Penjimatan kertas - Penjimatan air - Kempen hijau | D24: Tidak melaksanakan sebarang program penjimatan tenaga/sumber | E24: Program penjimatan tenaga/sumber dirancang tetapi tidak dilaksanakan | F24: Program penjimatan tenaga/sumber dilaksanakan tetapi tidak melebihi 50% daripada cadangan | G24: Program penjimatan tenaga/sumber dilaksanakan melebihi 50% daripada cadangan | H24: Melaksanakan sekurang-kurangnya tiga program penjimatan tenaga/sumber secara aktif dan berterusan | I24: 3 | J24: 3 | K24: 3 | L24: 3
B25: 16 | C25: Melaksanakan program/usaha kitar semula peringkat agensi | D25: Tiada program/usaha kitar semula dilaksanakan | E25: Aktiviti kitar semula dirancang tetapi tidak dilaksanakan | F25: Aktiviti kitar semula dilaksanakan secara ad hoc tanpa sistem sokongan | G25: Aktiviti kitar semula dilaksanakan secara berkala dengan penyertaan sebahagian warga agensi | H25: Program/usaha kitar semula dilaksanakan secara sistematik dan disertai oleh semua warga agensi serta dipantau keberkesanannya | I25: 4 | J25: 4 | K25: 4 | L25: 4
B26: JUMLAH | I26: =SUM(I6:I12,I14:I15,I17:I19,I21:I22,I24:I25) -> 58 | J26: =SUM(J6:J12,J14:J15,J17:J19,J21:J22,J24:J25) -> 58 | K26: =SUM(K6:K12,K14:K15,K17:K19,K21:K22,K24:K25) -> 58 | L26: =SUM(L6:L12,L14:L15,L17:L19,L21:L22,L24:L25) -> 58

Sheet KOMPONEN B
B3: KOMPONEN B | I3: MARKAH | M3: CATATAN
B4: RUANG TEMPAT KERJA/ PEJABAT | D4: 1 | E4: 2 | F4: 3 | G4: 4 | H4: 5 | I4: ZON EFFEKTIF | J4: ZON KOMITED | K4: ZON SEPAKAT | L4: ZON AKTIF
B5: FIZIKAL
B6: B1) LANTAI
B7: 1 | C7: Memastikan lantai memenuhi kriteria yang berikut: - Selamat dan tidak licin - Tiada kekotoran/ sampah di lantai - Tidak berlubang/ pecah atau rosak - Tong sampah disediakan | D7: Lantai tidak bersih dan tidak memenuhi sebarang kriteria | E7: Lantai bersih tetapi terdapat kerosakan atau tompokan air; tong sampah tidak disediakan | F7: Lantai bersih dan tidak licin tetapi hanya memenuhi sebahagian kriteria | G7: Lantai bersih, tidak licin, tiada tompokan air dan tong sampah disediakan di kebanyakan kawasan | H7: Lantai bersih, tidak licin, tiada tompokan air dan tong sampah disediakan di semua kawasan serta diselenggara secara berkala | I7: 3 | J7: 4 | K7: 4 | L7: 5
B8: 2 | C8: Menyediakan program pemantauan dan memastikan jadual pembersihan dipatuhi | D8: Tiada program pembersihan lantai dilaksanakan | E8: Program pembersihan lantai dirancang tetapi tidak dilaksanakan | F8: Program pembersihan lantai dilaksanakan secara ad hoc tanpa jadual tetap | G8: Program pembersihan lantai dilaksanakan secara berkala dengan pemantauan asas | H8: Program pembersihan lantai dilaksanakan secara berkala, dipantau dan direkodkan dalam sistem dokumentasi agensi
B9: B2) DINDING DAN SILING
B10: 3 | C10: Memastikan dinding dan siling bersih daripada kekotoran dan dalam keadaan baik | D10: Terdapat kerosakan dan kekotoran yang ketara pada dinding dan siling | E10: Dinding dan siling dalam keadaan sederhana; terdapat kekotoran atau kerosakan kecil | F10: Dinding dan siling bersih tetapi terdapat sedikit kerosakan kosmetik | G10: Dinding dan siling bersih dan dalam keadaan baik di kebanyakan kawasan | H10: Dinding dan siling bersih, dalam keadaan baik tanpa sebarang kerosakan serta diselenggara secara berkala | I10: 3 | J10: 4 | K10: 2 | L10: 4
B11: 4 | C11: Menyediakan hiasan yang bersesuaian dan selaras dengan imej korporat | D11: Tiada hiasan disediakan atau hiasan tidak langsung mencerminkan imej korporat | E11: Hiasan disediakan tetapi tidak konsisten dengan identiti visual atau tema korporat | F11: Hiasan disediakan dan mencerminkan sebahagian elemen imej korporat (warna, logo, slogan) | G11: Hiasan disediakan secara menyeluruh dan selaras dengan imej korporat di kebanyakan ruang | H11: Hiasan disediakan secara menyeluruh, konsisten, dan memperkukuh imej korporat di semua ruang serta menarik perhatian secara profesional dan kreatif | I11: 1 | J11: 3 | K11: 4 | L11: 5
B12: B3) LAMPU DAN SOKET
B13: 5 | C13: Memastikan semua lampu bersih, berfungsi dan dalam keadaan baik | D13: Kebanyakan lampu tidak berfungsi dan terdapat lampu rosak | E13: Sebahagian besar lampu tidak berfungsi, ada lampu yang rosak dan tidak dibersihkan | F13: Kebanyakan lampu berfungsi tetapi tidak bersih dan ada lampu yang rosak | G13: Semua lampu berfungsi tetapi tidak bersih sepenuhnya atau ada kekotoran ringan | H13: Semua lampu bersih, berfungsi dan dalam keadaan baik serta diselenggara secara berkala | I13: 3 | J13: 4 | K13: 4 | L13: 3
B14: 6 | C14: Memastikan soket elektrik berfungsi dan dalam keadaan baik | D14: Kebanyakan soket elektrik tidak berfungsi dan berisiko keselamatan | E14: Sebahagian besar soket elektrik tidak berfungsi atau dalam keadaan tidak selamat | F14: Kebanyakan soket elektrik berfungsi tetapi dalam keadaan kurang baik atau tidak bersih | G14: Semua soket elektrik berfungsi tetapi tidak bersih sepenuhnya atau tidak diselenggara | H14: Semua soket elektrik berfungsi, bersih dan dalam keadaan baik serta diselenggara secara berkala | I14: 4 | J14: 4 | K14: 3 | L14: 3
B15: B4)SUSUN ATUR PERALATAN
B16: 7 | C16: Menyemak/menyusun susunan laci meja/kabinet boleh gerak (mobile pedestal) | D16: Susunan pedestal tidak seragam dan tidak mengikut fungsi penggunaan | E16: Susunan pedestal tidak mengikut SOP EKSA (tiada penanda lantai, pengecaman visual, atau keseimbangan ruang) | F16: Pedestal disusun mengikut sebahagian kriteria EKSA yang disyorkan | G16: Pedestal disusun mengikut semua kriteria EKSA yang disyorkan dan digunakan secara konsisten | H16: Pedestal disusun mengikut semua kriteria EKSA, diselenggara secara berkala dan dimanfaatkan secara optimum | I16: 3 | J16: 5 | K16: 4 | L16: 5
B17: 8 | C17: Memastikan peralatan kerja di atas meja/kabinet dalam keadaan teratur dan kemas | D17: Peralatan tidak disusun, tidak teratur dan tidak kemas langsung | E17: Peralatan disusun tetapi terdapat barangan berlebihan, tidak relevan dengan tugas atau hiasan keterlaluan | F17: Peralatan disusun memenuhi sebahagian kriteria EKSA (komputer, dulang masuk/keluar, folder, hiasan minimum) | G17: Peralatan disusun memenuhi semua kriteria EKSA secara kekal dan konsisten | H17: Peralatan disusun memenuhi semua kriteria EKSA, diselenggara secara berkala dan dimanfaatkan secara optimum | I17: 3 | J17: 3 | K17: 3 | L17: 4
B18: B5)KEADAAN PERALATAN
B19: 9 | C19: Menyusun alat tulis dengan kemas dan teratur di atas meja/tulutang kerja | D19: Alat tulis tidak disusun langsung dan berselerak | E19: Sebahagian alat tulis tidak disusun dengan kemas dan teratur | F19: Sebahagian alat tulis disusun dengan kemas dan teratur | G19: Semua alat tulis disusun dengan kemas dan teratur | H19: Semua alat tulis disusun dengan kemas, teratur dan mengikut kategori/fungsi penggunaan | I19: 2 | J19: 4 | K19: 4 | L19: 4
B20: 10 | C20: Memastikan semua peralatan dalam keadaan baik dan boleh digunakan | D20: Semua peralatan tidak dalam keadaan baik dan tidak boleh digunakan | E20: Sebahagian peralatan tidak dalam keadaan baik dan tidak boleh digunakan | F20: Sebahagian peralatan dalam keadaan baik dan boleh digunakan | G20: Semua peralatan dalam keadaan baik dan boleh digunakan | H20: Semua peralatan dalam keadaan baik, boleh digunakan dan disusun dengan kemas serta dipantau secara berkala | I20: 4 | J20: 5 | K20: 4 | L20: 5
B21: 11 | C21: Menyusun semua barang keperluan dengan kemas dan teratur | D21: Tiada barang keperluan disusun | E21: Barang keperluan disusun tetapi tidak kemas dan tidak teratur | F21: Sebahagian barang keperluan disusun dengan kemas dan teratur | G21: Semua barang keperluan disusun dengan kemas dan teratur | H21: Semua barang keperluan disusun dengan kemas, teratur dan mengikut kategori/ fungsi | I21: 3 | J21: 5 | K21: 4 | L21: 4
B22: 12 | C22: Memperkenal tatacara penggunaan peralatan kepada pengguna | D22: Tiada tatacara penggunaan diperkenalkan | E22: Sebahagian peralatan tiada tatacara penggunaan diperkenalkan | F22: Sebahagian peralatan mempunyai tatacara penggunaan diperkenalkan | G22: Semua peralatan mempunyai tatacara penggunaan diperkenalkan | H22: Tatacara penggunaan diperkenalkan dan dipamerkan secara jelas untuk rujukan pengguna | I22: 2 | J22: 5 | K22: 1 | L22: 4
B23: 13 | C23: Memastikan peralatan diselenggara mengikut jadual | D23: Tiada jadual penyelenggaraan disediakan | E23: Jadual penyelenggaraan disediakan tetapi tidak dilaksanakan | F23: Jadual penyelenggaraan disediakan tetapi tidak konsisten dilaksanakan | G23: Jadual penyelenggaraan disediakan dan dilaksanakan mengikut jadual | H23: Jadual penyelenggaraan disediakan, dilaksanakan mengikut jadual dan direkodkan secara sistematik | I23: 4 | J23: 4 | K23: 1 | L23: 1
B24: 14 | C24: Memperkenal arahan/notis bagi penggunaan peralatan | D24: Tiada arahan/notis diperkenalkan | E24: Sebahagian peralatan tiada arahan/notis diperkenalkan | F24: Sebahagian peralatan mempunyai arahan/notis diperkenalkan | G24: Semua peralatan mempunyai arahan/notis diperkenalkan | H24: Arahan/notis diperkenalkan dan dipamerkan secara jelas untuk rujukan pengguna | I24: 3 | J24: 5 | K24: 1 | L24: 4
B25: B6) PELABELAN DAN PAPAN TANDA/ TANDA ARAH
B26: 15 | C26: Menyediakan tanda nama pegawai/kakitangan pada bilik atau ruang kerja/kubikel yang seragam | D26: Tiada tanda nama pegawai disediakan | E26: Sebahagian bilik/kubikel ada tanda nama tetapi tidak seragam | F26: Sebahagian bilik/kubikel ada tanda nama yang seragam | G26: Semua bilik/kubikel ada tanda nama yang seragam dan mudah dibaca | H26: Semua bilik/kubikel ada tanda nama yang seragam, mudah dibaca dan menunjukkan identiti organisasi secara profesional | I26: 3 | J26: 5 | K26: 5 | L26: 2
B27: 16 | C27: Menyediakan label yang bersesuaian dan seragam bagi tong kitar semula | D27: Tiada label langsung pada tong kitar semula | E27: Label disediakan tetapi tidak lengkap atau tidak jelas | F27: Label lengkap dan jelas tetapi tidak seragam antara tong | G27: Label lengkap, jelas dan seragam pada semua tong | H27: Label lengkap, jelas, seragam dan direka bentuk menarik serta mudah difahami oleh semua warga agensi | I27: 4 | J27: 2 | K27: 5
B28: 17 | C28: Menggunakan papan tanda/tanda arah yang sesuai dan mudah difahami | D28: Tiada papan tanda/tanda arah disediakan | E28: Papan tanda/tanda arah disediakan tetapi tidak sesuai atau sukar difahami | F28: Sebahagian papan tanda/tanda arah sesuai dan mudah difahami | G28: Semua papan tanda/tanda arah sesuai dan mudah difahami | H28: Semua papan tanda/tanda arah sesuai, mudah difahami, direka bentuk menarik dan menunjukkan identiti organisasi | I28: 4 | J28: 5 | K28: 4 | L28: 4
B29: 18 | C29: Meletakkan papan tanda/tanda arah pada lokasi yang strategik dan mudah dilihat | D29: Tiada papan tanda/tanda arah atau diletakkan di lokasi yang tidak strategik | E29: Sebahagian papan tanda/tanda arah diletakkan di lokasi yang kurang sesuai | F29: Sebahagian besar papan tanda/tanda arah diletakkan di lokasi strategik dan mudah dilihat | G29: Semua papan tanda/tanda arah diletakkan di lokasi strategik dan mudah dilihat | H29: Semua papan tanda/tanda arah diletakkan di lokasi strategik, mudah dilihat dan direka bentuk menarik serta konsisten dengan identiti organisasi | I29: 3 | J29: 5 | K29: 4 | L29: 4
B30: B7) RUANG TEMPAT KERJA/ PEJABAT
B31: 19 | C31: Menyediakan perhiasan yang minimum dan selaras dengan imej korporat | D31: Hiasan keterlaluan dan tidak selaras dengan imej korporat | E31: Hiasan minimum tetapi tidak selaras dengan imej korporat | F31: Hiasan minimum dan selaras dengan imej korporat | G31: Hiasan dalam keadaan baik, tidak berdebu dan tidak mengganggu fungsi ruang kerja | H31: Hiasan dalam keadaan baik, tidak berdebu, disusun dengan kemas dan memperkukuh imej korporat | I31: 2 | J31: 2 | K31: 5 | L31: 5
B32: 20 | C32: Memastikan perhiasan yang digunakan tidak berunsur keagamaan dan politik | D32: Terdapat perhiasan berunsur keagamaan dan politik | E32: Sebahagian perhiasan berunsur keagamaan dan politik | F32: Sebahagian perhiasan bebas daripada unsur keagamaan dan politik | G32: Semua perhiasan bebas daripada unsur keagamaan dan politik | H32: Semua perhiasan bebas daripada unsur keagamaan dan politik serta selaras dengan imej korporat dan prinsip EKSA | I32: 4 | J32: 5 | K32: 5 | L32: 5
B33: B8) KEPERLUAN UMUM
B34: 21 | C34: Menyedia dan memaparkan pelan lantai di bilik/ ruang gunasama yang mudah dilihat | D34: Pelan lantai tidak disediakan | E34: Pelan lantai disediakan tetapi tidak dikemas kini | F34: Sebahagian pelan lantai dikemas kini tetapi tidak dipamerkan | G34: Semua bilik/ruang mempunyai pelan lantai yang dikemas kini | H34: Semua bilik/ruang mempunyai pelan lantai yang dikemas kini serta dipamerkan di tempat yang sesuai dan mudah dirujuk | I34: 5 | J34: 5 | K34: 3.5 | L34: 3 | M34: ZON SEPAKAT: Sebahagian bilik atau ruang mempunyai pelan lantai yang dikemaskini
B35: 22 | C35: Memaparkan Senarai Aset Alih Kerajaan (KEW.PA-7) di semua bilik/ ruang | D35: KEW.PA-7 tidak disediakan | E35: KEW.PA-7 disediakan tetapi tidak dikemas kini | F35: Sebahagian KEW.PA-7 dikemas kini tetapi tidak dipamerkan | G35: Semua bilik/ruang mempunyaKEW.PA-7 yang dikemas kini | H35: Semua bilik/ruang mempunyai KEW.PA-7 yang dikemas kini serta dipamerkan di tempat yang sesuai dan mudah dirujuk | I35: 4 | J35: 5 | K35: 3.5 | L35: 2 | M35: ZON SEPAKAT: Semua bilik atau ruang mempunyai KEW.PA-7 tetapi terdapat sebahagian yang tidak dikemaskini
B36: 23 | C36: Melantik Pegawai Bertanggungjawab (PIC) dan mempamerkan nombor untuk dihubungi | D36: Tiada PIC dilantik dan tiada nombor untuk dihubungi | E36: Sebahagian ruang/bilik mempunyai PIC tetapi tiada nombor untuk dihubungi | F36: Sebahagian ruang/bilik mempunyai PIC dan nombor untuk dihubungi | G36: Semua ruang/bilik mempunyai PIC tetapi nombor tidak dipamerkan dengan jelas | H36: Semua ruang/bilik mempunyai PIC dan nombor untuk dihubungi yang dipamerkan secara jelas dan konsisten | I36: 5 | J36: 5 | K36: 5 | L36: 4
B37: 24 | C37: Menyedia dan mempamerkan carta organisasi di ruang pejabat | D37: Tiada carta organisasi disediakan | E37: Carta organisasi disediakan tetapi tidak dipamerkan | F37: Carta organisasi disediakan dan dipamerkan tetapi tidak dikemas kini | G37: Carta organisasi disediakan dan dipamerkan tetapi tidak lengkap | H37: Carta organisasi disediakan, lengkap, dikemas kini dan dipamerkan secara profesional | I37: 1 | J37: 5 | K37: 5 | L37: 5
B38: 25 | C38: Merancang dan melaksanakan inisiatif/aktiviti peningkatan persekitaran tempat kerja | D38: Tiada inisiatif dirancang atau dilaksanakan | E38: Inisiatif dirancang tetapi tidak dilaksanaka | F38: Inisiatif dilaksanakan tetapi tidak dinilai atau direkodkan | G38: Inisiatif dilaksanakan dan dinilai secara asas | H38: Inisiatif dilaksanakan, dinilai secara sistematik dan direkodkan untuk penambahbaikan berterusan | I38: 4 | J38: 3 | K38: 1 | L38: 5
B39: B9) MEJA KERJA WARGA/ KUBIKEL KERJA
B40: 26 | C40: Memastikan meja kerja kemas dan tersusun dengan baik | D40: Meja kerja tidak kemas dan tidak tersusun langsung | E40: Meja kerja tidak kemas tetapi tersusun secara asas | F40: Meja kerja kemas tetapi susunan tidak sistematik | G40: Meja kerja kemas dan tersusun dengan baik | H40: Meja kerja kemas, tersusun dengan sangat baik dan selaras dengan prinsip EKSA | I40: 3 | J40: 4 | K40: 4 | L40: 3
B41: 27 | C41: Menyediakan paparan identiti warga serta elemen korporat yang seragam dan kemas | D41: Tiada paparan identiti atau elemen korporat | E41: Paparan identiti disediakan tetapi tiada elemen korporat | F41: Paparan identiti dan elemen korporat disediakan tetapi tidak seragam | G41: Paparan identiti dan elemen korporat disediakan tetapi tidak kemas | H41: Paparan identiti dan elemen korporat disediakan secara seragam, kemas dan selaras dengan imej organisasi | I41: 2 | J41: 3 | K41: 5 | L41: 3
B42: 28 | C42: Menyediakan ruang kerja yang minimum dan selesa | D42: Ruang kerja tidak minimum dan tidak selesa | E42: Ruang kerja hanya memenuhi keperluan minimum | F42: Ruang kerja hanya memenuhi keperluan keselesaan | G42: Ruang kerja memenuhi keperluan minimum dan selesa | H42: Ruang kerja disediakan secara optimum, selesa, ergonomik dan menyokong produktiviti | I42: 3 | J42: 5 | K42: 4 | L42: 4
...

Sheet KOMPONEN C
B3: KOMPONEN C | I3: MARKAH
B4: TEMPAT UMUM | D4: 1 | E4: 2 | F4: 3 | G4: 4 | H4: 5 | I4: ZON EFFEKTIF | J4: ZON KOMITED | K4: ZON SEPAKAT | L4: ZON AKTIF
B5: C1) LOBI UTAMA/ RUANG HADAPAN
B6: 1 | C6: Memastikan persekitaran lobi utama/ruang hadapan memenuhi kriteria berikut: - Bersih - Tidak berdebu - Kemas - Ceria - Selaras dengan imej korporat | D6: Persekitaran lobi kotor dan tidak memenuhi sebarang kriteria | E6: Persekitaran lobi bersih dan kemas tetapi tidak menyerlah dengan imej korporat | F6: Persekitaran lobi memenuhi tiga kriteria asas | G6: Persekitaran lobi memenuhi empat kriteria asas dan selaras dengan imej korporat | H6: Persekitaran lobi ceria, kemas dan selaras dengan imej korporat serta memberikan imej positif kepada warga dan pelanggan | I6: 2 | J6: 5 | K6: 5
B7: 2 | C7: Memaparkan maklumat korporat berkaitan agensi yang terkini Contoh: Visi, Misi, Pengurusan Atasan, Moto, Piagam Pelanggan | D7: Tiada maklumat dipaparkan | E7: Maklumat dipaparkan tetapi tidak lengkap dan tidak terkini | F7: Maklumat dipaparkan tetapi tidak terkini | G7: Memaparkan satu hingga tiga maklumat yang disyorkan dan terkini | H7: Semua maklumat yang disyorkan dipaparkan secara lengkap, terkini dan selaras dengan imej korporat | I7: 4 | J7: 5 | K7: 5
B8: 3 | C8: Menyediakan perkara berkaitan agensi yang disyorkan di ruang hadapan Contoh: Buku kedatangan pelawat, direktori pegawai, sudut informasi, perhiasan selaras imej korporat | D8: Tiada perkara disediakan | E8: Hanya sebahagian perkara disediakan secara minimum | F8: Perkara disediakan secara berasingan dan tidak konsisten | G8: Perkara disediakan secara hampir lengkap dan menarik | H8: Semua perkara disyorkan disediakan secara lengkap, menarik dan reka bentuk memberi penarikan kepada warga dan pelanggan | I8: 4 | J8: 5 | K8: 5
B9: C2) KAUNTER UTAMA
B10: 4 | C10: Memastikan imej korporat dipraktikkan dan kaunter utama menyediakan perkara berikut: - Sistem maklum balas pelanggan - Direktori pegawai/agensi - Borang/brosur berkaitan - Bahan bacaan/informasi - Info mengenai agensi/piagam pelanggan - Maklumat kadar bayaran (sekiranya ada) | D10: Kaunter utama tidak menyediakan sebarang perkara yang disyorkan | E10: Kaunter utama menyediakan antara satu hingga dua perkara yang disyorkan | F10: Kaunter utama menyediakan antara tiga hingga empat perkara yang disyorkan | G10: Kaunter utama menyediakan antara lima hingga enam perkara yang disyorkan | H10: Kaunter utama menyediakan semua perkara yang disyorkan serta disusun dengan menarik dan selaras dengan imej korporat | I10: 4
B11: 5 | C11: Memastikan kaunter utama sentiasa bersih, kemas dan ceria | D11: Kaunter utama tidak bersih, tidak kemas dan kotor | E11: Kaunter utama bersih tetapi tidak kemas dan ceria | F11: Kaunter utama bersih dan kemas tetapi tidak ceria | G11: Kaunter utama ceria tetapi tidak cukup bersih dan kemas | H11: Kaunter utama ceria, sangat bersih dan tersusun kemas | I11: 3
B12: 6 | C12: Melaksanakan usaha-usaha ke arah konsep ❝delighting the customer❞ Contoh: Persekitaran yang kondusif dan kemudahan sokongan dilaksanakan. | D12: Usaha-usaha ke arah “delighting the customer” langsung tidak dilaksanakan | E12: Sebahagian persekitaran ataupun tiada kemudahan sokongan diberikan di kaunter utama | F12: Usaha-usaha “delighting the customer” dilaksanakan secara tidak konsisten atau separuh jalan sahaja | G12: Persekitaran kaunter utama adalah kondusif dengan sedikit kemudahan sokongan diberikan kepada pelanggan | H12: Persekitaran kaunter utama sangat kondusif dan dilengkapi pelbagai kemudahan sokongan untuk keselesaan pelanggan | I12: 4
B13: 7 | C13: Menyediakan perkhidmatan yang mesra pelanggan | D13: Perkhidmatan tidak mesra pelanggan langsung (tiada interaksi, tiada bantuan) | E13: Perkhidmatan disediakan tetapi tidak mesra atau tidak konsisten | F13: Perkhidmatan mesra pelanggan disediakan secara asas tetapi tidak menyeluruh | G13: Perkhidmatan mesra pelanggan disediakan secara menyeluruh dan konsisten | H13: Perkhidmatan mesra pelanggan disediakan secara menyeluruh, konsisten dan disokong dengan latihan, SOP serta pemantauan berkala | I13: 4
B14: 8 | C14: Menyedia dan memaparkan carta aliran perkhidmatan yang dikemas kini | D14: Carta aliran langsung tidak disediakan | E14: Carta aliran disediakan tetapi tidak dikemas kini dan tidak dipamerkan | F14: Carta aliran disediakan dan dipamerkan tetapi tidak dikemas kini | G14: Carta aliran disediakan, dikemas kini dan dipamerkan di lokasi strategik | H14: Carta aliran disediakan, dikemas kini, dipamerkan secara strategik dan direka bentuk menarik serta mudah difahami oleh pelanggan | I14: 1 | M14: Zon Effektif: (CUMA ADA PIAGAM PELANGGAN)
B15: C3) RUANG MENUNGGU
B16: 9 | C16: Memastikan persekitaran ruang menunggu pelanggan memenuhi kriteria berikut: - Bersih - Terjaga - Selamat - Kemas | D16: Ruang menunggu tidak memenuhi sebarang kriteria | E16: Ruang menunggu pelanggan tidak kemas dan tidak selamat | F16: Ruang menunggu pelanggan bersih dan terjaga tetapi tidak kemas | G16: Ruang menunggu pelanggan memenuhi tiga kriteria | H16: Ruang menunggu pelanggan memenuhi semua kriteria dan selaras dengan imej korporat | I16: 4 | J16: 5 | K16: 5
B17: 10 | C17: Memaparkan bahan bacaan/informasi yang sesuai dan tersedia serta disusun dengan kemas (jika ada) | D17: Bahan bacaan tidak disediakan | E17: Bahan bacaan disediakan tetapi tidak disusun kemas | F17: Bahan bacaan/informasi disediakan tetapi terhad dan tidak kemas | G17: Bahan bacaan/informasi disediakan dalam pelbagai pilihan tetapi tidak kemas | H17: Bahan bacaan/informasi disediakan dalam pelbagai pilihan dan disusun dengan kemas serta menarik | I17: 3 | J17: 1 | K17: 5
B18: 11 | C18: Memastikan kerusi berada dalam keadaan baik dan mencukupi | D18: Semua kerusi rosak dan tidak boleh digunakan | E18: Sebahagian kerusi berada dalam keadaan baik | F18: Sebahagian kerusi berada dalam keadaan rosak | G18: Kerusi berada dalam keadaan baik tetapi tidak mencukupi | H18: Kerusi berada dalam keadaan baik, mencukupi dan selesa digunakan | I18: 5 | J18: 5 | K18: 5
B19: C4) LALUAN UTAMA/ KORIDOR
B20: 12 | C20: Memastikan susunan peralatan atau hiasan sepanjang laluan kemas, bersih dan teratur | D20: Semua susunan peralatan atau hiasan tidak kemas dan berselerak | E20: Sebahagian susunan peralatan atau hiasan tidak kemas dan tidak bersih | F20: Sebahagian susunan peralatan atau hiasan kemas dan teratur | G20: Semua susunan peralatan atau hiasan kemas dan bersih tetapi tidak teratur | H20: Semua susunan peralatan atau hiasan kemas, bersih, teratur dan selaras dengan imej korporat | I20: 2 | J20: 4.5 | K20: 4.5 | M20: Zon Sepakat: sebahagian tidak selaras dengan imej korporat | N20: Zon Komited : Hampir semua bersih, teratur, kemas tetapi sebahagian tidak berimej korporat
B21: 13 | C21: Memastikan tiada halangan di sepanjang laluan ke pintu kecemasan | D21: Terdapat halangan di sepanjang laluan ke pintu kecemasan | E21: Sebahagian laluan ke pintu kecemasan terhalang | F21: Sebahagian besar laluan ke pintu kecemasan bebas daripada halangan | G21: Semua laluan ke pintu kecemasan bebas daripada halangan tetapi tidak ditanda dengan jelas | H21: Semua laluan ke pintu kecemasan bebas daripada halangan dan ditanda dengan jelas serta selaras dengan pelan keselamatan | I21: 4 | J21: 3 | K21: 5
B22: C5) BILIK MESYUARAT
B23: 14 | C23: Memastikan semua peralatan seperti meja, kerusi, mikrofon dan komputer disusun dengan kemas dan bersih | D23: Semua peralatan tidak disusun dan tidak bersih | E23: Sebahagian peralatan disusun tetapi tidak bersih | F23: Sebahagian peralatan disusun dengan baik dan bersih | G23: Semua peralatan disusun dengan baik tetapi tidak bersih | H23: Semua peralatan disusun dengan baik, bersih dan selaras dengan prinsip EKSA serta imej korporat | J23: 5
B24: 15 | C24: Memastikan persediaan bilik mesyuarat dalam keadaan bersih dan kemas | D24: Persediaan bilik mesyuarat tidak lengkap dan tidak kemas serta tidak bersih | E24: Persediaan bilik mesyuarat tidak lengkap dan tidak kemas | F24: Persediaan bilik mesyuarat tidak lengkap tetapi bersih | G24: Persediaan bilik mesyuarat lengkap tetapi tidak kemas | H24: Persediaan bilik mesyuarat lengkap, bersih, kemas dan selaras dengan imej korporat serta menyokong kelancaran mesyuarat | J24: 5
B25: C6) PERPUSTAKAAN/ PUSAT SUMBER
B26: 16 | C26: Memastikan ruang perpustakaan/pusat sumber bersih, kemas dan teratur | D26: Ruang perpustakaan kotor, tidak kemas dan tidak teratur | E26: Ruang perpustakaan kurang bersih, kurang kemas dan tidak teratur | F26: Ruang perpustakaan bersih, kemas dan teratur secara asas | G26: Ruang perpustakaan bersih, kemas dan teratur serta selaras dengan imej korporat | H26: Ruang perpustakaan sangat bersih, kemas, teratur dan menyokong suasana pembelajaran kondusif | K26: 5
B27: 17 | C27: Menyediakan sistem rekod peminjaman bahan bacaan yang kemas dan teratur | D27: Tiada sistem rekod peminjaman disediakan | E27: Sistem rekod disediakan tetapi tidak kemas dan tidak teratur | F27: Sistem rekod disediakan, kemas dan teratur secara asas | G27: Sistem rekod disediakan, kemas dan teratur serta mudah dirujuk | H27: Sistem rekod disediakan, kemas, teratur, dikemas kini dan selaras dengan SOP pengurusan bahan bacaan | K27: 5
B28: C7) SURAU/ BILIK SOLAT
B29: 18 | C29: Memastikan barang-barang/peralatan solat disediakan dan disusun dengan teratur Contoh: Telekung, Sejadah, Al-Quran, Rehal, Yasin, Tafsir | D29: Peralatan solat tidak mencukupi dan tidak disusun | E29: Peralatan solat mencukupi tetapi tidak disusun dengan kemas | F29: Peralatan solat mencukupi dan disusun secara asas | G29: Peralatan solat mencukupi dan disusun dengan kemas serta mudah dicapai | H29: Peralatan solat mencukupi, disusun dengan kemas, bersih dan selaras dengan imej korporat | K29: 5 | L29: 2
B30: 19 | C30: Menyediakan ruang yang sesuai untuk menjalankan ibadah seperti membaca Al-Quran dan solat | D30: Hanya satu sudut kecil disediakan tanpa kemudahan sokongan | E30: Dua kemudahan disediakan tetapi tidak selesa | F30: Dua kemudahan disediakan secara asas | G30: Dua kemudahan disediakan dan selesa tetapi tidak lengkap | H30: Semua kemudahan disediakan, selesa, lengkap dan menyokong suasana ibadah yang tenang serta kondusif | K30: 5 | L30: 2
B31: 20 | C31: Memastikan al-Quran/bahan bacaan sentiasa kemas dan dalam keadaan baik | D31: Semua al-Quran/bahan bacaan tidak kemas dan dalam keadaan tidak baik | E31: Sebahagian al-Quran/bahan bacaan tidak kemas dan tidak lengkap | F31: Sebahagian al-Quran/bahan bacaan kemas dan dalam keadaan baik | G31: Semua al-Quran/bahan bacaan kemas dan dalam keadaan baik | H31: Semua al-Quran/ bahan bacaan kemas, bersih, lengkap dan disusun secara sistematik | K31: 5
B32: 21 | C32: Memastikan surau/bilik solat sentiasa bersih, berbau harum dan tidak berhabuk | D32: Surau/bilik solat tidak bersih, berbau dan berhabuk | E32: Surau/bilik solat bersih tetapi berhabuk dan tidak berbau harum | F32: Surau/bilik solat bersih dan berbau harum tetapi berhabuk | G32: Surau/bilik solat bersih, berbau harum dan tidak berhabuk | H32: Surau/bilik solat bersihm berbau harum, tidak berhabuk dan selesa digunakan | K32: 5 | L32: 4
B33: 22 | C33: Memastikan surau tidak berbau, tidak berhabuk dan tidak kotor | D33: Surau berbau, berhabuk dan kotor | E33: Surau berbau dan berhabuk tetapi tidak kotor | F33: Surau tidak berbau dan tidak berhabuk tetapi kotor | G33: Surau tidak berbau, tidak berhabuk dan tidak kotor | H33: Surau tidak berbau, tidak berhabuk dan tidak kotor dab diselenggara secara berkala | K33: 5 | L33: 4
B34: 23 | C34: Memastikan tempat wuduk bersih dan selamat digunakan | D34: Tempat wuduk kotor dan licin | E34: Tempat wuduk bersih tetapi tidak selamat digunakan | F34: Tempat wuduk bersih dan selamat digunakan secara asas | G34: Tempat wuduk bersih, selamat dan diselenggara secara berkala | H34: Tempat wuduk bersih, selamat, selesa dan dilengkapi kemudahan sokongan | K34: 4
B35: C8) PANTRI/ TEMPAT MINUM
B36: 24 | C36: Memastikan peralatan berada dalam keadaan baik, tersusun dan boleh digunakan | D36: Semua peralatan rosak dan tidak boleh digunakan | E36: Peralatan boleh digunakan tetapi tidak dibersihkan | F36: Peralatan boleh digunakan tetapi tidak disusun kemas | G36: Peralatan boleh digunakan dan bersih tetapi ada kekurangan kecil | H36: Peralatan boleh digunakan, bersih dan disusun kemas | J36: 4 | K36: 5
B37: 25 | C37: Memastikan pantri bersih, tidak berbau dan tidak mencemarkan pemandangan | D37: Pantri kotor, berbau dan tidak teratur | E37: Pantri bersih tetapi berbau dan tidak kemas | F37: Pantri bersih dan tidak berbau tetapi tidak kemas | G37: Pantri bersih, tidak berbau dan kemas tetapi tidak sistematik | H37: Pantri sangat bersih, tidak berbau, kemas dan tersusun secara estetik | J37: 4 | K37: 3
B38: C9) TANDAS
B39: 26 | C39: Memastikan persekitaran tandas bersih dan kering | D39: Persekitaran tandas kotor dan basah | E39: Persekitaran tandas basah tetapi tidak terlalu kotor | F39: Persekitaran tandas kering tetapi tidak bersih | G39: Persekitaran tandas kering dan bersih tetapi tidak kemas | H39: Persekitaran tandas kering sangat bersih dan selamat digunakan | I39: 5 | J39: 4.5 | K39: 5 | L39: 5
B40: 27 | C40: Memastikan peralatan tandas berada dalam keadaan baik dan boleh digunakan | D40: Semua peralatan tandas rosak dan tidak boleh digunakan | E40: Sebahagian peralatan tandas boleh digunakan tetapi tidak bersih | F40: Sebahagian peralatan tandas bersih tetapi tidak berfungsi | G40: Semua peralatan tandas bersih dan boleh digunakan tetapi tidak lengkap | H40: Semua peralatan tandas bersih, lengkap dan berfungsi dengan baik | I40: 5 | J40: 5 | K40: 5 | L40: 5
B41: 28 | C41: Memastikan tandas tidak berbau | D41: Tandas berbau busuk dan tidak menyenangkan | E41: Tandas berbau tetapi masih boleh digunakan | F41: Sebahagian tandas tidak berbau | G41: Tandas tidak berbau dan ada pengudaraan asa | H41: Tandas tidak berbau, ada pengudaraan baik dan penyegar udara | I41: 5 | J41: 4 | K41: 5 | L41: 5
B42: 29 | C42: Memaparkan pemakluman seperti jadual tugas, etika dan peraturan penggunaan tandas | D42: Tiada sebarang pemakluman dipaparkan | E42: Pemakluman dipaparkan tetapi tidak lengkap dan tidak dikemas kini | F42: Pemakluman dipaparkan dan dikemas kini tetapi tidak mudah difahami | G42: Pemakluman dipaparkan, lengkap dan mudah difahami tetapi tidak menarik | H42: Pemakluman dipaparkan secara lengkap, dikemas kini, mudah difahami dan direka bentuk menarik serta selaras dengan imej korporat | I42: 1 | J42: 5 | K42: 4 | L42: 5
...

Sheet KOMPONEN D
B3: KOMPONEN D | I3: MARKAH
B4: BILIK PEMBELAJARAN & PENGAJARAN | D4: 1 | E4: 2 | F4: 3 | G4: 4 | H4: 5 | I4: ZON EFFEKTIF | J4: ZON KOMITED | K4: ZON SEPAKAT | L4: ZON AKTIF
B5: D1) BENGKEL
B6: 1 | C6: Memastikan ruang bengkel bersih, selamat dan tersusun | D6: Bengkel kotor, berhabuk dan tidak selamat | E6: Bengkel bersih tetapi tidak selamat dan tidak tersusun | F6: Bengkel bersih dan selamat tetapi tidak tersusun | G6: Bengkel bersih, selamat dan sebahagian besar tersusun | H6: Bengkel bersih, selamat, tersusun dan menyokong pembelajaran hands-on | I6: 3 | J6: 4
B7: 2 | C7: Menyediakan peralatan bengkel dalam keadaan baik dan boleh digunakan | D7: Peralatan rosak dan tidak boleh digunakan | E7: Sebahagian peralatan boleh digunakan tetapi tidak diselenggara | F7: Peralatan boleh digunakan tetapi tidak lengkap | G7: Semua peralatan boleh digunakan dan diselenggara secara berkala | H7: Semua peralatan boleh digunakan, diselenggara dan disusun mengikut zon kerja | I7: 4 | J7: 4
B8: D2) BILIK KULIAH
B9: 3 | C9: Memastikan bilik kuliah bersih, kemas dan selesa | D9: Bilik kuliah kotor dan tidak kemas | E9: Bilik kuliah bersih tetapi tidak kemas dan tidak selesa | F9: Bilik kuliah bersih dan kemas tetapi tidak selesa | G9: Bilik kuliah bersih, kemas dan selesa secara asas | H9: Bilik kuliah bersih, kemas, selesa dan menyokong suasana pembelajaran kondusif | I9: 3 | K9: 4
B10: 4 | C10: Menyediakan bahan bantu mengajar dan paparan maklumat akademik | D10: Tiada bahan bantu mengajar atau paparan maklumat | E10: Bahan bantu mengajar disediakan tetapi tidak dikemas kini | F10: Bahan bantu mengajar dan maklumat akademik disediakan tetapi tidak lengkap | G10: Bahan bantu mengajar dan maklumat akademik lengkap tetapi tidak menarik | H10: Bahan bantu mengajar dan maklumat akademik lengkap, dikemas kini dan direka bentuk menarik | I10: 4 | K10: 3
B11: D3) DEWAN KULIAH
B12: 5 | C12: Memastikan susun atur kerusi, meja dan peralatan AV kemas dan berfungsi | D12: Susun atur tidak kemas dan peralatan AV tidak berfungsi | E12: Susun atur kemas tetapi peralatan AV tidak berfungsi | F12: Susun atur kemas dan sebahagian peralatan AV berfungsi | G12: Susun atur kemas dan semua peralatan AV berfungsi | H12: Susun atur kemas, semua peralatan AV berfungsi dan menyokong pembelajaran interaktif | K12: 2.5 | M12: Zon Sepakat: Susun atur tidak kemas tetapi semua peralatan AV berfungsi
B13: 6 | C13: Menyediakan ruang dewan kuliah yang selesa dan selaras dengan imej korporat | D13: Ruang tidak selesa dan tidak selaras dengan imej korporat | E13: Ruang selesa tetapi tidak selaras dengan imej korporat | F13: Ruang selesa dan sebahagian selaras dengan imej korporat | G13: Ruang selesa dan selaras dengan imej korporat secara asas | H13: Ruang selesa, selaras dengan imej korporat dan menyokong aktiviti rasmi | K13: 3
B14: D4) MAKMAL
B15: 7 | C15: Memastikan makmal bersih, selamat dan mematuhi SOP keselamatan | D15: Makmal kotor, tidak selamat dan tiada SOP | E15: Makmal bersih tetapi tidak selamat dan tiada SOP | F15: Makmal bersih dan selamat tetapi tiada SOP | G15: Makmal bersih, selamat dan SOP dipamerkan | H15: Makmal bersih, selamat, SOP dipamerkan dan dipatuhi | J15: 5 | K15: 4
B16: 8 | C16: Menyediakan peralatan makmal dalam keadaan baik dan diselenggara | D16: Peralatan rosak dan tidak boleh digunakan | E16: Sebahagian peralatan boleh digunakan tetapi tidak diselenggara | F16: Peralatan boleh digunakan tetapi tidak lengkap | G16: Semua peralatan boleh digunakan dan diselenggara secara berkala | H16: Semua peralatan boleh digunakan, diselenggara, dilabel dan direkodkan | J16: 3.5 | K16: 3.5 | M16: ZON SEPAKAT: Tiada jadual penyelenggaraan | N16: Zon Komited : Kerusi dan Meja Komputer di MM1 rosak
B17: D5) BILIK JAHITAN
B18: 9 | C18: Memastikan ruang bilik jahitan bersih, kemas dan selamat digunakan | D18: Ruang kotor, berhabuk dan tidak selamat | E18: Ruang bersih tetapi tidak kemas dan tidak selamat | F18: Ruang bersih dan kemas tetapi tidak selamat | G18: Ruang bersih, kemas dan selamat secara asas | H18: Ruang bersih, kemasm selamat dan menyokong pembelajaran teknikal | L18: 5
B19: 10 | C19: Menyediakan mesin jahit dan peralatan dalam keadaan baik dan disusun kemas | D19: Mesin dan peralatan rosak dan tidak disusun | E19: Sebahagian mesin berfungsi tetapi tidak disusun | F19: Mesin dan peralatan berfungsi tetapi tidak lengkap | G19: Semua mesin dan peralatan berfungsi dan disusun secara asas | H19: Semua mesin dan peralatan berfungsi, lengkap dan disusun mengikut zon kerja | L19: 5
B20: D5) BILIK MASAKAN
B21: 11 | C21: Memastikan ruang bilik masakan bersih, bebas bau dan selamat digunakan | D21: Ruang kotor, berbau dan tidak selamat | E21: Ruang bersih tetapi berbau dan tidak selamat | F21: Ruang bersih dan selamat tetapi berbau | G21: Ruang bersih, bebas bau dan selamat secara asas | H21: Ruang bersih, bebas bau, selamat dan menyokong pembelajaran kulinari | I21: 5
B22: 12 | C22: Menyediakan peralatan memasak dalam keadaan baik dan disusun kemas | D22: Peralatan rosak dan tidak disusun | E22: Sebahagian peralatan berfungsi tetapi tidak disusun | F22: Peralatan berfungsi tetapi tidak lengkap | G22: Semua peralatan berfungsi dan disusun secara asas | H22: Semua peralatan berfungsi, lengkap dan disusun mengikut kategori dan keselamatan dapur | I22: 5
B23: JUMLAH | I23: =SUM(I6:I7,I9:I10,I12:I13,I15:I16,I18:I19,I21:I22) -> 24 | J23: =SUM(J6:J7,J9:J10,J12:J13,J15:J16,J18:J19,J21:J22) -> 16.5 | K23: =SUM(K6:K7,K9:K10,K12:K13,K15:K16,K18:K19,K21:K22) -> 20 | L23: =SUM(L6:L7,L9:L10,L12:L13,L15:L16,L18:L19,L21:L22) -> 10
I24: =COUNT(I6,I7,I9,I10,I21,I22) -> 6 | J24: =COUNT(J6,J7,J15,J16) -> 4 | K24: =COUNT(K9,K10,K12,K13,K15,K16) -> 6 | L24: =COUNT(L18,L19) -> 2
I25: =I24*5 -> 30 | J25: =J24*5 -> 20 | K25: =K24*5 -> 30 | L25: =L24*5 -> 10

Sheet KOMPONEN E
A4: KOMPONEN E | H4: MARKAH
A5: KESELAMATAN PERSEKITARAN | C5: 1 | D5: 2 | E5: 3 | F5: 4 | G5: 5 | H5: ZON EFFEKTIF | I5: ZON KOMITED | J5: ZON SEPAKAT | K5: ZON AKTIF
A6: E1) PELAN TINDAKAN KECEMASAN
A7: 1 | B7: Menyediakan Pelan Tindakan Kecemasan yang mengandungi: i. Arahan Keselamatan ii. Latihan pengungsian bangunan, Latihan Kebakaran (fire-drill) iii. Tanda Amaran iv. Pelan laluan kecemasan dan tempat berkumpul v. Tanda arah laluan kecemasan.n | C7: Tiada Pelan Tindakan Kecemasan | D7: Pelan Tindakan Kecemasan mengandungi dua kriteria yang disyorkan | E7: Pelan Tindakan Kecemasan mengandungi tiga kriteria yang disyorkan | F7: Pelan Tindakan Kecemasan mengandungi empat kriteria yang disyorkan | G7: Pelan Tindakan Kecemasan mengandungi kesemua kriteria yang disyorkan
A8: 2 | B8: Menyediakan lampu kecemasan yang mudah dilihat, berfungsi dengan baik dan tiada halangan. | C8: Tiada lampu kecemasan | E8: Ada lampu kecemasan dan berfungsi tetapi terhalang | G8: Ada lampu kecemasan, berfungsi dan tidak terhalang
A9: E2) PENDAWAIAN/KABEL
A10: 3 | B10: Memastikan pendawaian elektrik/ telefon/kabel komputer/mesin/ peralatan dalam keadaan kemas, teratur dan selamat. | C10: Pendawaian dalam keadaan tidak kemas, tidak teratur dan tidak selamat | E10: Sebahagian pendawaian dalam keadaan kemas, teratur dan selamat | G10: Semua pendawaian dalam keadaan kemas, teratur dan selamat
A11: E3) PERALATAN PENCEGAHAN KEBAKARAN
A12: 4 | B12: Memastikan alat pemadam api menepati kriteria yang berikut: i. Penyelengaraan secara berkala ii. Mempunyai tatacara penggunaan iii. Berkeadaan bersih iv. Diletakkan di tempat yang sesuai dan mudah dicapai | C12: Tiada alat pemadam api disediakan | E12: Alat pemadam api menepati sebahagian kriteria yang disyorkan | G12: Alat pemadam api menepati kesemua kriteria yang disyorkan
A13: E4) LALUAN/TANGGA KECEMASAN
A14: 5 | B14: Memastikan tiada halangan di laluan/tangga/pintu kecemasan. | C14: Terdapat halangan di laluan/tangga kecemasan | G14: Tiada halangan di laluan/tangga kecemasan
A15: E5) KUNCI
A16: 6 | B16: Memastikan anak kunci dilabelkan/ditandai dan memenuhi tatacara keselamatan. | C16: Anak kunci tidak dilabelkan/ ditandai | E16: Anak kunci dilabelkan/ ditandai tetapi tidak memenuhi tatacara keselamatan | G16: Anak kunci dilabelkan/ ditandai dan memenuhi tatacara keselamatan
A17: 7 | B17: Memastikan anak kunci disimpan di dalam ruang penyimpanan yang selamat. | C17: Anak kunci tidak disimpan di dalam peti keselamatan | G17: Anak kunci disimpan di dalam peti keselamatan
A18: 8 | B18: Memastikan senarai anak kunci disimpan dengan selamat oleh pegawai bertanggungjawab. | C18: Senarai anak kunci tidak disimpan | G18: Senarai anak kunci disimpan dengan selamat
A19: 9 | B19: Menyediakan buku log peminjaman kunci dan dikemas kini. | C19: Buku log peminjaman kunci tidak disediakan | E19: Buku log peminjaman kunci disediakan tetapi tidak dikemas kini | G19: Buku log peminjaman kunci disediakan dan dikemas kini

Sheet MARKAH AUDIT
A2: MARKAH AUDIT DALAM EKSA 2025 KOLEJ KOMUNITI HULU LANGAT
A7: BIL. | B7: KOMPONEN | C7: MARKAH PENUH ZON EFFEKTIF | D7: MARKAH ZON EFFEKTIF | E7: % MARKAH ZON EFFEKTIF | F7: MARKAH PENUH ZON KOMITED | G7: MARKAH ZON KOMITED | H7: % MARKAH ZON KOMITED | I7: MARKAH PENUH ZON SEPAKAT | J7: MARKAH ZON SEPAKAT | K7: % MARKAH ZON SEPAKAT | L7: MARKAH PENUH ZON AKTIF | M7: MARKAH ZON AKTIF | N7: % MARKAH ZON AKTIF
A8: A. | B8: KEPERLUAN UTAMA PELAKSANAAN | C8: 80 | D8: ='KOMPONEN A'!I26 -> 58 | E8: =D8/C8 -> 0.725 | F8: 80 | G8: ='KOMPONEN A'!K26 -> 58 | H8: =G8/F8 -> 0.725 | I8: 80 | J8: ='KOMPONEN A'!I26 -> 58 | K8: =J8/I8 -> 0.725 | L8: 80 | M8: ='KOMPONEN A'!I26 -> 58 | N8: =M8/L8 -> 0.725
A9: B. | B9: RUANG TEMPAT KERJA / PEJABAT | C9: 205 | D9: ='KOMPONEN B'!I75 -> 139 | E9: =D9/C9 -> 0.67804878 | F9: 205 | G9: ='KOMPONEN B'!J75 -> 184 | H9: =G9/F9 -> 0.89756098 | I9: 190 | J9: ='KOMPONEN B'!K75 -> 141 | K9: =J9/I9 -> 0.74210526 | L9: 160 | M9: ='KOMPONEN B'!L75 -> 124 | N9: =M9/L9 -> 0.775
A10: C. | B10: TEMPAT UMUM | C10: 90 | D10: ='KOMPONEN C'!I44 -> 65 | E10: =D10/C10 -> 0.72222222 | F10: 85 | G10: ='KOMPONEN C'!J44 -> 71 | H10: =G10/F10 -> 0.83529412 | I10: 115 | J10: ='KOMPONEN C'!K44 -> 106.5 | K10: =J10/I10 -> 0.92608696 | L10: 40 | M10: ='KOMPONEN C'!L44 -> 32 | N10: =M10/L10 -> 0.8
A11: D. | B11: BILIK PEMBELAJARAN & PENGAJARAN | C11: 30 | D11: ='KOMPONEN D'!I23 -> 24 | E11: =D11/C11 -> 0.8 | F11: 20 | G11: ='KOMPONEN D'!J23 -> 16.5 | H11: =G11/F11 -> 0.825 | I11: 30 | J11: ='KOMPONEN D'!K23 -> 20 | K11: =J11/I11 -> 0.66666667 | L11: 10 | M11: ='KOMPONEN D'!L23 -> 10 | N11: =M11/L11 -> 1
A12: JUMLAH MARKAH | C12: =SUM(C8:C11) -> 405 | D12: =SUM(D8:D11) -> 286 | E12: =D12/C12 -> 0.70617284 | F12: =SUM(F8:F11) -> 390 | G12: =SUM(G8:G11) -> 329.5 | H12: =G12/F12 -> 0.84487179 | I12: =SUM(I8:I11) -> 415 | J12: =SUM(J8:J11) -> 325.5 | K12: =J12/I12 -> 0.78433735 | L12: =SUM(L8:L11) -> 290 | M12: =SUM(M8:M11) -> 224 | N12: =M12/L12 -> 0.77241379
A13: PERATUS MARKAH ZON | D13: =(D12/C12) -> 0.70617284 | E13: =(D12/C12) -> 0.70617284 | G13: =(G12/F12) -> 0.84487179 | H13: =(G12/F12) -> 0.84487179 | J13: =(J12/I12) -> 0.78433735 | K13: =(J12/I12) -> 0.78433735 | M13: =(M12/L12) -> 0.77241379 | N13: =(M12/L12) -> 0.77241379
A14: PERATUS MARKAH KESELURUHAN | C14: =(SUM(D12,G12,J12,M12)/SUM(C12,F12,I12,L12)) -> 0.77666667
D17: PENGESAHAN
D18: WAKIL PENGURUSAN
D23: TANDATANGAN:
D24: NAMA :
D25: TARIKH:

Sheet LAPORAN
A2: LAPORAN PENILAIAN AUDIT EKSA 2025 KOLEJ KOMUNITI HULU LANGAT
A8: TARIKH AUDIT: 14 Oktober 2025
A11: BIL. | B11: KOMPONEN | C11: MARKAH PENUH ZON EFFEKTIF | D11: MARKAH ZON EFFEKTIF | E11: MARKAH PENUH ZON KOMITED | F11: MARKAH ZON KOMITED | G11: MARKAH PENUH ZON SEPAKAT | H11: MARKAH ZON SEPAKAT | I11: MARKAH PENUH ZON AKTIF | J11: MARKAH ZON AKTIF
A12: A. | B12: KEPERLUAN UTAMA PELAKSANAAN | C12: 80 | D12: ='KOMPONEN A'!I26 -> 58 | E12: 80 | F12: ='KOMPONEN A'!K26 -> 58 | G12: 80 | H12: ='KOMPONEN A'!I26 -> 58 | I12: 80 | J12: ='KOMPONEN A'!I26 -> 58
A13: B. | B13: RUANG TEMPAT KERJA / PEJABAT | C13: 205 | D13: ='KOMPONEN B'!I75 -> 139 | E13: 205 | F13: ='KOMPONEN B'!J75 -> 184 | G13: 190 | H13: ='KOMPONEN B'!K75 -> 141 | I13: 160 | J13: ='KOMPONEN B'!L75 -> 124
A14: C. | B14: TEMPAT UMUM | C14: 90 | D14: ='KOMPONEN C'!I44 -> 65 | E14: 85 | F14: ='KOMPONEN C'!J44 -> 71 | G14: 115 | H14: ='KOMPONEN C'!K44 -> 106.5 | I14: 40 | J14: ='KOMPONEN C'!L44 -> 32
A15: D. | B15: BILIK PEMBELAJARAN & PENGAJARAN | C15: 30 | D15: ='KOMPONEN D'!I23 -> 24 | E15: 20 | F15: ='KOMPONEN D'!J23 -> 16.5 | G15: 30 | H15: ='KOMPONEN D'!K23 -> 20 | I15: 10 | J15: ='KOMPONEN D'!L23 -> 10
A16: E. | B16: KESELAMATAN PERSEKITARAN | C16: 45 | E16: 45 | G16: 45 | I16: 45
A17: JUMLAH MARKAH | C17: =SUM(C12:C16) -> 450 | D17: =SUM(D12:D15) -> 286 | E17: =SUM(E12:E16) -> 435 | F17: =SUM(F12:F15) -> 329.5 | G17: =SUM(G12:G16) -> 460 | H17: =SUM(H12:H15) -> 325.5 | I17: =SUM(I12:I16) -> 335 | J17: =SUM(J12:J15) -> 224
A18: PERATUS MARKAH ZON | D18: =(D17/C17) -> 0.63555556 | F18: =(F17/E17) -> 0.75747126 | H18: =(H17/G17) -> 0.7076087 | J18: =(J17/I17) -> 0.66865672
A19: PERATUS MARKAH KESELURUHAN | C19: =(SUM(D17,F17,H17,J17)/SUM(C17,E17,G17,I17)) -> 0.69345238
A22: PENGESAHAN | D22: PENGESAHAN
A23: KETUA JURUAUDIT | D23: WAKIL PENGURUSAN
A28: TANDATANGAN: | D28: TANDATANGAN:
A29: NAMA : MAZWINA HANIM BINTI ABU BAKAR | D29: NAMA :
A30: TARIKH: | D30: TARIKH:
